<sdf version='1.9'>
  <world name='empty'>
    <physics name='1ms' type='ignored'>
      <max_step_size>0.001</max_step_size>
      <real_time_factor>1</real_time_factor>
      <real_time_update_rate>1000</real_time_update_rate>
    </physics>
    <plugin name='gz::sim::systems::Physics' filename='gz-sim-physics-system'/>
    <plugin name='gz::sim::systems::UserCommands' filename='gz-sim-user-commands-system'/>
    <plugin name='gz::sim::systems::SceneBroadcaster' filename='gz-sim-scene-broadcaster-system'/>
    <plugin name='gz::sim::systems::Sensors' filename='gz-sim-sensors-system'>
      <render_engine>ogre2</render_engine>
    </plugin>
    <plugin name='gz::sim::systems::Contact' filename='gz-sim-contact-system'/>
    <plugin name='gz::sim::systems::Imu' filename='gz-sim-imu-system'/>
    <gravity>0 0 -9.8</gravity>
    <magnetic_field>6e-06 2.3e-05 -4.2e-05</magnetic_field>
    <atmosphere type='adiabatic'/>
    <scene>
      <ambient>0.4 0.4 0.4 1</ambient>
      <background>0.7 0.7 0.7 1</background>
      <shadows>true</shadows>
    </scene>
    <model name='ground_plane'>
      <static>true</static>
      <link name='link'>
        <collision name='collision'>
          <geometry>
            <plane>
              <normal>0 0 1</normal>
              <size>100 100</size>
            </plane>
          </geometry>
          <surface>
            <friction>
              <ode/>
            </friction>
            <bounce/>
            <contact/>
          </surface>
        </collision>
        <visual name='visual'>
          <geometry>
            <plane>
              <normal>0 0 1</normal>
              <size>100 100</size>
            </plane>
          </geometry>
          <material>
            <ambient>0.8 0.8 0.8 1</ambient>
            <diffuse>0.8 0.8 0.8 1</diffuse>
            <specular>0.8 0.8 0.8 1</specular>
          </material>
        </visual>
        <pose>0 0 0 0 -0 0</pose>
        <inertial>
          <pose>0 0 0 0 -0 0</pose>
          <mass>1</mass>
          <inertia>
            <ixx>1</ixx>
            <ixy>0</ixy>
            <ixz>0</ixz>
            <iyy>1</iyy>
            <iyz>0</iyz>
            <izz>1</izz>
          </inertia>
        </inertial>
        <enable_wind>false</enable_wind>
      </link>
      <pose>0 0 0 0 -0 0</pose>
      <self_collide>false</self_collide>
    </model>
    <model name='mini_r1'>
      <link name='base_link'>
        <inertial>
          <pose>0.01374 -1e-05 0.05693 0 -0 0</pose>
          <mass>1.36056</mass>
          <inertia>
            <ixx>0.0093903800000000003</ixx>
            <ixy>2.0868200000000002e-06</ixy>
            <ixz>-0.00084205599999999999</ixz>
            <iyy>0.018101200000000001</iyy>
            <iyz>3.1647799999999998e-07</iyz>
            <izz>0.022560400000000001</izz>
          </inertia>
        </inertial>
        <collision name='base_link_collision'>
          <pose>0 0 0 0 0 0</pose>
          <geometry>
            <mesh>
              <scale>1 1 1</scale>
              <uri>file:///home/yusuf/ros2_mahe_ugv/install/mini_r1_v1_description/share/mini_r1_v1_description/meshes/base_link.STL</uri>
            </mesh>
          </geometry>
          <surface>
            <contact>
              <ode/>
            </contact>
            <friction>
              <ode>
                <mu>0.20000000000000001</mu>
                <mu2>0.20000000000000001</mu2>
              </ode>
            </friction>
          </surface>
        </collision>
        <collision name='base_link_fixed_joint_lump__CAM_collision_1'>
          <pose>0.1658 0.00050302 0.078 0 0 0</pose>
          <geometry>
            <mesh>
              <scale>1 1 1</scale>
              <uri>file:///home/yusuf/ros2_mahe_ugv/install/mini_r1_v1_description/share/mini_r1_v1_description/meshes/CAM.STL</uri>
            </mesh>
          </geometry>
          <surface>
            <contact>
              <ode/>
            </contact>
            <friction>
              <ode/>
            </friction>
          </surface>
        </collision>
        <collision name='base_link_fixed_joint_lump__IMU_collision_2'>
          <pose>0.095 0 0.08 0 0 0</pose>
          <geometry>
            <mesh>
              <scale>1 1 1</scale>
              <uri>file:///home/yusuf/ros2_mahe_ugv/install/mini_r1_v1_description/share/mini_r1_v1_description/meshes/IMU.STL</uri>
            </mesh>
          </geometry>
          <surface>
            <contact>
              <ode/>
            </contact>
            <friction>
              <ode/>
            </friction>
          </surface>
        </collision>
        <collision name='base_link_fixed_joint_lump__LIDAR_collision_3'>
          <pose>0.095 0 0.12 0 0 0</pose>
          <geometry>
            <cylinder>
              <length>0.040000000000000001</length>
              <radius>0.037999999999999999</radius>
            </cylinder>
          </geometry>
          <surface>
            <contact>
              <ode/>
            </contact>
            <friction>
              <ode/>
            </friction>
            <bounce/>
          </surface>
        </collision>
        <visual name='base_link_visual'>
          <pose>0 0 0 0 0 0</pose>
          <geometry>
            <mesh>
              <scale>1 1 1</scale>
              <uri>file:///home/yusuf/ros2_mahe_ugv/install/mini_r1_v1_description/share/mini_r1_v1_description/meshes/base_link.STL</uri>
            </mesh>
          </geometry>
          <material>
            <ambient>0.01 0.01 0.01 1</ambient>
            <diffuse>0.01 0.01 0.01 1</diffuse>
            <specular>0.1 0.1 0.1 1</specular>
            <emissive>0 0 0 0</emissive>
          </material>
        </visual>
        <visual name='base_link_fixed_joint_lump__CAM_visual_1'>
          <pose>0.1658 0.00050302 0.078 0 0 0</pose>
          <geometry>
            <mesh>
              <scale>1 1 1</scale>
              <uri>file:///home/yusuf/ros2_mahe_ugv/install/mini_r1_v1_description/share/mini_r1_v1_description/meshes/CAM.STL</uri>
            </mesh>
          </geometry>
          <material>
            <ambient>0.5 0.5 0.5 1</ambient>
            <diffuse>0.5 0.5 0.5 1</diffuse>
            <specular>0.1 0.1 0.1 1</specular>
            <emissive>0 0 0 0</emissive>
          </material>
        </visual>
        <visual name='base_link_fixed_joint_lump__IMU_visual_2'>
          <pose>0.095 0 0.08 0 0 0</pose>
          <geometry>
            <mesh>
              <scale>1 1 1</scale>
              <uri>file:///home/yusuf/ros2_mahe_ugv/install/mini_r1_v1_description/share/mini_r1_v1_description/meshes/IMU.STL</uri>
            </mesh>
          </geometry>
          <material>
            <diffuse>0.625 0.625 0.625 1</diffuse>
            <ambient>0.625 0.625 0.625 1</ambient>
          </material>
        </visual>
        <visual name='base_link_fixed_joint_lump__LIDAR_visual_3'>
          <pose>0.095 0 0.12 0 0 0</pose>
          <geometry>
            <cylinder>
              <length>0.040000000000000001</length>
              <radius>0.037999999999999999</radius>
            </cylinder>
          </geometry>
          <material>
            <ambient>0.05 0.05 0.05 1</ambient>
            <diffuse>0.05 0.05 0.05 1</diffuse>
            <specular>0.1 0.1 0.1 1</specular>
            <emissive>0 0 0 0</emissive>
          </material>
        </visual>
        <self_collide>true</self_collide>
        <gravity>true</gravity>
        <sensor name='camera' type='camera'>
          <pose>0.1658 0.000503 0.078 0 -0 0</pose>
          <topic>/r1_mini/camera</topic>
          <update_rate>30</update_rate>
          <enable_metrics>false</enable_metrics>
          <camera name='__default__'>
            <pose>0 0 0 0 -0 0</pose>
            <horizontal_fov>1.089</horizontal_fov>
            <image>
              <width>640</width>
              <height>480</height>
              <format>RGB_INT8</format>
              <anti_aliasing>4</anti_aliasing>
            </image>
            <camera_info_topic>__default__</camera_info_topic>
            <trigger_topic></trigger_topic>
            <triggered>false</triggered>
            <clip>
              <near>0.050000000000000003</near>
              <far>8</far>
            </clip>
            <save enabled='false'>
              <path>__default__</path>
            </save>
            <visibility_mask>4294967295</visibility_mask>
            <noise>
              <type>none</type>
              <mean>0</mean>
              <stddev>0</stddev>
            </noise>
            <distortion>
              <k1>0</k1>
              <k2>0</k2>
              <k3>0</k3>
              <p1>0</p1>
              <p2>0</p2>
              <center>0.5 0.5</center>
            </distortion>
            <lens>
              <type>stereographic</type>
              <scale_to_hfov>true</scale_to_hfov>
              <cutoff_angle>1.5708</cutoff_angle>
              <env_texture_size>256</env_texture_size>
            </lens>
            <optical_frame_id></optical_frame_id>
          </camera>
        </sensor>
        <sensor name='imu' type='imu'>
          <pose>0.095 0 0.08 0 -0 0</pose>
          <topic>/r1_mini/imu</topic>
          <update_rate>100</update_rate>
          <enable_metrics>false</enable_metrics>
          <imu>
            <orientation_reference_frame>
              <localization>CUSTOM</localization>
              <custom_rpy>0 0 0</custom_rpy>
              <grav_dir_x>1 0 0</grav_dir_x>
            </orientation_reference_frame>
            <angular_velocity>
              <x>
                <noise type='gaussian'>
                  <mean>0</mean>
                  <stddev>0.00020000000000000001</stddev>
                  <bias_mean>0</bias_mean>
                  <bias_stddev>0</bias_stddev>
                  <dynamic_bias_stddev>0</dynamic_bias_stddev>
                  <dynamic_bias_correlation_time>0</dynamic_bias_correlation_time>
                  <precision>0</precision>
                </noise>
              </x>
              <y>
                <noise type='gaussian'>
                  <mean>0</mean>
                  <stddev>0.00020000000000000001</stddev>
                  <bias_mean>0</bias_mean>
                  <bias_stddev>0</bias_stddev>
                  <dynamic_bias_stddev>0</dynamic_bias_stddev>
                  <dynamic_bias_correlation_time>0</dynamic_bias_correlation_time>
                  <precision>0</precision>
                </noise>
              </y>
              <z>
                <noise type='gaussian'>
                  <mean>0</mean>
                  <stddev>0.00020000000000000001</stddev>
                  <bias_mean>0</bias_mean>
                  <bias_stddev>0</bias_stddev>
                  <dynamic_bias_stddev>0</dynamic_bias_stddev>
                  <dynamic_bias_correlation_time>0</dynamic_bias_correlation_time>
                  <precision>0</precision>
                </noise>
              </z>
            </angular_velocity>
            <linear_acceleration>
              <x>
                <noise type='gaussian'>
                  <mean>0</mean>
                  <stddev>0.017000000000000001</stddev>
                  <bias_mean>0</bias_mean>
                  <bias_stddev>0</bias_stddev>
                  <dynamic_bias_stddev>0</dynamic_bias_stddev>
                  <dynamic_bias_correlation_time>0</dynamic_bias_correlation_time>
                  <precision>0</precision>
                </noise>
              </x>
              <y>
                <noise type='gaussian'>
                  <mean>0</mean>
                  <stddev>0.017000000000000001</stddev>
                  <bias_mean>0</bias_mean>
                  <bias_stddev>0</bias_stddev>
                  <dynamic_bias_stddev>0</dynamic_bias_stddev>
                  <dynamic_bias_correlation_time>0</dynamic_bias_correlation_time>
                  <precision>0</precision>
                </noise>
              </y>
              <z>
                <noise type='gaussian'>
                  <mean>0</mean>
                  <stddev>0.017000000000000001</stddev>
                  <bias_mean>0</bias_mean>
                  <bias_stddev>0</bias_stddev>
                  <dynamic_bias_stddev>0</dynamic_bias_stddev>
                  <dynamic_bias_correlation_time>0</dynamic_bias_correlation_time>
                  <precision>0</precision>
                </noise>
              </z>
            </linear_acceleration>
            <enable_orientation>true</enable_orientation>
          </imu>
        </sensor>
        <sensor name='lidar' type='gpu_lidar'>
          <pose>0.095 0 0.12 0 -0 0</pose>
          <topic>/r1_mini/lidar</topic>
          <update_rate>10</update_rate>
          <enable_metrics>false</enable_metrics>
          <lidar>
            <scan>
              <horizontal>
                <samples>360</samples>
                <resolution>1</resolution>
                <min_angle>-3.1400000000000001</min_angle>
                <max_angle>3.1400000000000001</max_angle>
              </horizontal>
              <vertical>
                <samples>1</samples>
                <min_angle>0</min_angle>
                <max_angle>0</max_angle>
                <resolution>1</resolution>
              </vertical>
            </scan>
            <range>
              <min>0.12</min>
              <max>30</max>
              <resolution>0.11</resolution>
            </range>
            <noise>
              <type>none</type>
              <mean>0</mean>
              <stddev>0</stddev>
            </noise>
            <visibility_mask>4294967295</visibility_mask>
          </lidar>
        </sensor>
        <pose>0 0 0 0 -0 0</pose>
        <enable_wind>false</enable_wind>
      </link>
      <joint name='J_TR_LF' type='revolute'>
        <pose>0 0 0 0 -0 0</pose>
        <parent>base_link</parent>
        <child>TR_LF</child>
        <axis>
          <xyz>0 1 0</xyz>
          <limit>
            <lower>-10000000000000000</lower>
            <upper>10000000000000000</upper>
            <effort>inf</effort>
            <velocity>inf</velocity>
            <stiffness>100000000</stiffness>
            <dissipation>1</dissipation>
          </limit>
          <dynamics>
            <spring_reference>0</spring_reference>
            <spring_stiffness>0</spring_stiffness>
            <damping>0</damping>
            <friction>0</friction>
          </dynamics>
        </axis>
      </joint>
      <link name='TR_LF'>
        <pose>0.13 0.11371 0.027801 1e-06 -1e-06 -0</pose>
        <inertial>
          <pose>0 0 0 0 -0 0</pose>
          <mass>0.30043999999999998</mass>
          <inertia>
            <ixx>0.00051575000000000004</ixx>
            <ixy>2.2786e-09</ixy>
            <ixz>-1.1409e-08</ixz>
            <iyy>0.00086728</iyy>
            <iyz>-1.8296000000000001e-10</iyz>
            <izz>0.00051568999999999996</izz>
          </inertia>
        </inertial>
        <collision name='TR_LF_collision'>
          <pose>0 0 0 0 0 0</pose>
          <geometry>
            <mesh>
              <scale>1 1 1</scale>
              <uri>file:///home/yusuf/ros2_mahe_ugv/install/mini_r1_v1_description/share/mini_r1_v1_description/meshes/TR_LF.STL</uri>
            </mesh>
          </geometry>
          <surface>
            <contact>
              <ode/>
            </contact>
            <friction>
              <ode>
                <mu>0.20000000000000001</mu>
                <mu2>0.20000000000000001</mu2>
              </ode>
            </friction>
          </surface>
        </collision>
        <visual name='TR_LF_visual'>
          <pose>0 0 0 0 0 0</pose>
          <geometry>
            <mesh>
              <scale>1 1 1</scale>
              <uri>file:///home/yusuf/ros2_mahe_ugv/install/mini_r1_v1_description/share/mini_r1_v1_description/meshes/TR_LF.STL</uri>
            </mesh>
          </geometry>
          <material>
            <ambient>0.01 0.01 0.01 1</ambient>
            <diffuse>0.01 0.01 0.01 1</diffuse>
            <specular>0.1 0.1 0.1 1</specular>
            <emissive>0 0 0 0</emissive>
          </material>
        </visual>
        <self_collide>true</self_collide>
        <enable_wind>false</enable_wind>
      </link>
      <joint name='J_TR_LR' type='revolute'>
        <pose>0 0 0 0 -0 0</pose>
        <parent>base_link</parent>
        <child>TR_LR</child>
        <axis>
          <xyz>0 1 0</xyz>
          <limit>
            <lower>-10000000000000000</lower>
            <upper>10000000000000000</upper>
            <effort>inf</effort>
            <velocity>inf</velocity>
            <stiffness>100000000</stiffness>
            <dissipation>1</dissipation>
          </limit>
          <dynamics>
            <spring_reference>0</spring_reference>
            <spring_stiffness>0</spring_stiffness>
            <damping>0</damping>
            <friction>0</friction>
          </dynamics>
        </axis>
      </joint>
      <link name='TR_LR'>
        <pose>-0.13 0.11371 0.0278 0 -0 0</pose>
        <inertial>
          <pose>0 0 0 0 -0 0</pose>
          <mass>0.30365799999999998</mass>
          <inertia>
            <ixx>0.00052402999999999998</ixx>
            <ixy>-2.2895e-09</ixy>
            <ixz>8.5108e-09</ixz>
            <iyy>0.00088002600000000001</iyy>
            <iyz>-6.8877999999999995e-11</iyz>
            <izz>0.00052397000000000001</izz>
          </inertia>
        </inertial>
        <collision name='TR_LR_collision'>
          <pose>0 0 0 0 0 0</pose>
          <geometry>
            <mesh>
              <scale>1 1 1</scale>
              <uri>file:///home/yusuf/ros2_mahe_ugv/install/mini_r1_v1_description/share/mini_r1_v1_description/meshes/TR_LR.STL</uri>
            </mesh>
          </geometry>
          <surface>
            <contact>
              <ode/>
            </contact>
            <friction>
              <ode>
                <mu>0.20000000000000001</mu>
                <mu2>0.20000000000000001</mu2>
              </ode>
            </friction>
          </surface>
        </collision>
        <visual name='TR_LR_visual'>
          <pose>0 0 0 0 0 0</pose>
          <geometry>
            <mesh>
              <scale>1 1 1</scale>
              <uri>file:///home/yusuf/ros2_mahe_ugv/install/mini_r1_v1_description/share/mini_r1_v1_description/meshes/TR_LR.STL</uri>
            </mesh>
          </geometry>
          <material>
            <ambient>0.01 0.01 0.01 1</ambient>
            <diffuse>0.01 0.01 0.01 1</diffuse>
            <specular>0.1 0.1 0.1 1</specular>
            <emissive>0 0 0 0</emissive>
          </material>
        </visual>
        <self_collide>true</self_collide>
        <enable_wind>false</enable_wind>
      </link>
      <joint name='J_TR_RF' type='revolute'>
        <pose>0 0 0 0 -0 0</pose>
        <parent>base_link</parent>
        <child>TR_RF</child>
        <axis>
          <xyz>0 1 0</xyz>
          <limit>
            <lower>-10000000000000000</lower>
            <upper>10000000000000000</upper>
            <effort>inf</effort>
            <velocity>inf</velocity>
            <stiffness>100000000</stiffness>
            <dissipation>1</dissipation>
          </limit>
          <dynamics>
            <spring_reference>0</spring_reference>
            <spring_stiffness>0</spring_stiffness>
            <damping>0</damping>
            <friction>0</friction>
          </dynamics>
        </axis>
      </joint>
      <link name='TR_RF'>
        <pose>0.13 -0.11371 0.0278 -0 -0 0</pose>
        <inertial>
          <pose>0 0 0 0 -0 0</pose>
          <mass>0.30043999999999998</mass>
          <inertia>
            <ixx>0.00051575000000000004</ixx>
            <ixy>2.2786e-09</ixy>
            <ixz>-1.1409e-08</ixz>
            <iyy>0.00086728</iyy>
            <iyz>-1.8296000000000001e-10</iyz>
            <izz>0.00051568999999999996</izz>
          </inertia>
        </inertial>
        <collision name='TR_RF_collision'>
          <pose>0 0 0 0 0 0</pose>
          <geometry>
            <mesh>
              <scale>1 1 1</scale>
              <uri>file:///home/yusuf/ros2_mahe_ugv/install/mini_r1_v1_description/share/mini_r1_v1_description/meshes/TR_RF.STL</uri>
            </mesh>
          </geometry>
          <surface>
            <contact>
              <ode/>
            </contact>
            <friction>
              <ode>
                <mu>0.20000000000000001</mu>
                <mu2>0.20000000000000001</mu2>
              </ode>
            </friction>
          </surface>
        </collision>
        <visual name='TR_RF_visual'>
          <pose>0 0 0 0 0 0</pose>
          <geometry>
            <mesh>
              <scale>1 1 1</scale>
              <uri>file:///home/yusuf/ros2_mahe_ugv/install/mini_r1_v1_description/share/mini_r1_v1_description/meshes/TR_RF.STL</uri>
            </mesh>
          </geometry>
          <material>
            <ambient>0.01 0.01 0.01 1</ambient>
            <diffuse>0.01 0.01 0.01 1</diffuse>
            <specular>0.1 0.1 0.1 1</specular>
            <emissive>0 0 0 0</emissive>
          </material>
        </visual>
        <self_collide>true</self_collide>
        <enable_wind>false</enable_wind>
      </link>
      <joint name='J_TR_RR' type='revolute'>
        <pose>0 0 0 0 -0 0</pose>
        <parent>base_link</parent>
        <child>TR_RR</child>
        <axis>
          <xyz>0 1 0</xyz>
          <limit>
            <lower>-10000000000000000</lower>
            <upper>10000000000000000</upper>
            <effort>inf</effort>
            <velocity>inf</velocity>
            <stiffness>100000000</stiffness>
            <dissipation>1</dissipation>
          </limit>
          <dynamics>
            <spring_reference>0</spring_reference>
            <spring_stiffness>0</spring_stiffness>
            <damping>0</damping>
            <friction>0</friction>
          </dynamics>
        </axis>
      </joint>
      <link name='TR_RR'>
        <pose>-0.13 -0.11269 0.027801 1e-06 -1e-06 -0</pose>
        <inertial>
          <pose>0 0 0 0 -0 0</pose>
          <mass>0.30043999999999998</mass>
          <inertia>
            <ixx>0.00051574699999999999</ixx>
            <ixy>2.2853e-09</ixy>
            <ixz>-5.4383000000000001e-09</ixz>
            <iyy>0.00086727699999999996</iyy>
            <iyz>4.9031e-11</iyz>
            <izz>0.00051568700000000002</izz>
          </inertia>
        </inertial>
        <collision name='TR_RR_collision'>
          <pose>0 0 0 0 0 0</pose>
          <geometry>
            <mesh>
              <scale>1 1 1</scale>
              <uri>file:///home/yusuf/ros2_mahe_ugv/install/mini_r1_v1_description/share/mini_r1_v1_description/meshes/TR_RR.STL</uri>
            </mesh>
          </geometry>
          <surface>
            <contact>
              <ode/>
            </contact>
            <friction>
              <ode>
                <mu>0.20000000000000001</mu>
                <mu2>0.20000000000000001</mu2>
              </ode>
            </friction>
          </surface>
        </collision>
        <visual name='TR_RR_visual'>
          <pose>0 0 0 0 0 0</pose>
          <geometry>
            <mesh>
              <scale>1 1 1</scale>
              <uri>file:///home/yusuf/ros2_mahe_ugv/install/mini_r1_v1_description/share/mini_r1_v1_description/meshes/TR_RR.STL</uri>
            </mesh>
          </geometry>
          <material>
            <ambient>0.01 0.01 0.01 1</ambient>
            <diffuse>0.01 0.01 0.01 1</diffuse>
            <specular>0.1 0.1 0.1 1</specular>
            <emissive>0 0 0 0</emissive>
          </material>
        </visual>
        <self_collide>true</self_collide>
        <enable_wind>false</enable_wind>
      </link>
      <plugin name='gz::sim::systems::DiffDrive' filename='gz-sim-diff-drive-system'>
        <odom_publisher_frequency>50</odom_publisher_frequency>
        <left_joint>J_TR_LF</left_joint>
        <left_joint>J_TR_LR</left_joint>
        <right_joint>J_TR_RF</right_joint>
        <right_joint>J_TR_RR</right_joint>
        <wheel_separation>0.2885</wheel_separation>
        <wheel_radius>0.065</wheel_radius>
        <max_wheel_torque>50</max_wheel_torque>
        <max_linear_acceleration>1.5</max_linear_acceleration>
        <topic>cmd_vel</topic>
        <publish_odom>true</publish_odom>
        <publish_odom_tf>false</publish_odom_tf>
        <publish_wheel_tf>true</publish_wheel_tf>
        <tf_topic>/r1_mini/odom_tf</tf_topic>
        <odom_topic>/r1_mini/odom</odom_topic>
        <frame_id>odom</frame_id>
        <child_frame_id>base_link</child_frame_id>
      </plugin>
      <plugin name='gz::sim::systems::JointStatePublisher' filename='gz-sim-joint-state-publisher-system'>
        <update_rate>100</update_rate>
        <topic>/r1_mini/joint_states</topic>
        <joint_name>J_TR_LF</joint_name>
        <joint_name>J_TR_LR</joint_name>
        <joint_name>J_TR_RF</joint_name>
        <joint_name>J_TR_RR</joint_name>
      </plugin>
      <frame name='J_CAM' attached_to='base_link'>
        <pose>0.1658 0.000503 0.078 0 -0 0</pose>
      </frame>
      <frame name='CAM' attached_to='J_CAM'/>
      <frame name='J_IMU' attached_to='base_link'>
        <pose>0.095 0 0.08 0 -0 0</pose>
      </frame>
      <frame name='IMU' attached_to='J_IMU'/>
      <frame name='J_LIDAR' attached_to='base_link'>
        <pose>0.095 0 0.12 0 -0 0</pose>
      </frame>
      <frame name='LIDAR' attached_to='J_LIDAR'/>
      <pose>-4e-05 4e-05 0.038175 -1.9e-05 7e-06 3.14025</pose>
      <static>false</static>
      <self_collide>false</self_collide>
    </model>
    <model name='finales'>
      <link name='link'>
        <visual name='visual'>
          <geometry>
            <mesh>
              <uri>file:///home/yusuf/ros2_mahe_ugv/install/mini_r1_v1_description/share/mini_r1_v1_description/meshes/finales.obj</uri>
            </mesh>
          </geometry>
        </visual>
        <collision name='collision'>
          <geometry>
            <mesh>
              <uri>file:///home/yusuf/ros2_mahe_ugv/install/mini_r1_v1_description/share/mini_r1_v1_description/meshes/finales.obj</uri>
            </mesh>
          </geometry>
        </collision>
        <pose>0 0 0 0 -0 0</pose>
        <inertial>
          <pose>0 0 0 0 -0 0</pose>
          <mass>1</mass>
          <inertia>
            <ixx>1</ixx>
            <ixy>0</ixy>
            <ixz>0</ixz>
            <iyy>1</iyy>
            <iyz>0</iyz>
            <izz>1</izz>
          </inertia>
        </inertial>
        <enable_wind>false</enable_wind>
      </link>
      <pose>1.36309 2.72506 -1.04222 -0 -0 0</pose>
      <static>true</static>
      <self_collide>false</self_collide>
    </model>
    <light name='sun' type='directional'>
      <pose>0 0 10 0 -0 0</pose>
      <cast_shadows>true</cast_shadows>
      <intensity>1</intensity>
      <direction>-0.5 0.1 -0.9</direction>
      <diffuse>0.8 0.8 0.8 1</diffuse>
      <specular>0.2 0.2 0.2 1</specular>
      <attenuation>
        <range>1000</range>
        <linear>0.01</linear>
        <constant>0.90000000000000002</constant>
        <quadratic>0.001</quadratic>
      </attenuation>
      <spot>
        <inner_angle>0</inner_angle>
        <outer_angle>0</outer_angle>
        <falloff>0</falloff>
      </spot>
    </light>
  </world>
</sdf>
